# The root function to throw exception.

function func1() {
    try {
        try {
            System.println('Nothing is thrown, good.');
        }
        finally {
            System.println('finally: func1-1');
        }
        System.println("Throw exception");
        throw RuntimeException("Oh, it's a careless mistake!");
    }
    finally {
        System.println('finally: func1-2');
    }
}

# Catches the exception from func1, but rethrow it.
function func2() {
    try {
        try {
            func1();
        }
        finally {
            System.println('finally: func2-1');
        }
    }
    catch (e) {
        System.println('catch: func2');
        throw;
    }
    finally {
        System.println('finally: func2-2');
    }
}

# No one catch the exception, but finally clause will be correctly working.
function func3() {
    try {
        try {
            func2();
        }
        finally {
            System.println('finally: func3-1');
        }
    }
    finally {
        System.println('finally: func3-2');
    }
}

# Starts the test.
try {
    func3();
}
catch (e) {
    System.println("%{e.type()}: %{e.what()}");
    e.printStackTrace();
}
finally {
    System.println('finally: main-block');
}

System.println("end-of-program.");
